<?xml version="1.0" ?>
<robot name="biped">

  <!-- 躯干 -->
  <link name="torso">
    <inertial>
      <origin xyz="0 0 0" />
      <mass value="2.0"/>
      <inertia ixx="0.05" iyy="0.05" izz="0.05" ixy="0" ixz="0" iyz="0"/>
    </inertial>
    <visual>
      <origin xyz="0 0 0" rpy="0 0 0"/>
      <geometry><box size="0.2 0.1 0.3"/></geometry>
      <material name="blue"><color rgba="0.2 0.2 0.8 1"/></material>
    </visual>
    <collision><geometry><box size="0.2 0.1 0.3"/></geometry></collision>
  </link>

  <!-- 左腿大腿 -->
  <link name="left_thigh">
    <inertial>
      <origin xyz="0 0 -0.075"/>
      <mass value="0.5"/>
      <inertia ixx="0.01" iyy="0.01" izz="0.01" ixy="0" ixz="0" iyz="0"/>
    </inertial>
    <visual><geometry><box size="0.05 0.05 0.15"/></geometry>
      <material name="red"><color rgba="0.8 0.2 0.2 1"/></material></visual>
    <collision><geometry><box size="0.05 0.05 0.15"/></geometry></collision>
  </link>

  <!-- 左腿小腿 -->
  <link name="left_shin">
    <inertial>
      <origin xyz="0 0 -0.075"/>
      <mass value="0.3"/>
      <inertia ixx="0.005" iyy="0.005" izz="0.005" ixy="0" ixz="0" iyz="0"/>
    </inertial>
    <visual><geometry><box size="0.04 0.04 0.15"/></geometry>
      <material name="green"><color rgba="0.2 0.8 0.2 1"/></material></visual>
    <collision><geometry><box size="0.04 0.04 0.15"/></geometry></collision>
  </link>

  <!-- 左脚 -->
  <link name="left_foot">
    <inertial>
      <origin xyz="0 0 0"/>
      <mass value="0.2"/>
      <inertia ixx="0.002" iyy="0.002" izz="0.002" ixy="0" ixz="0" iyz="0"/>
    </inertial>
    <visual><geometry><box size="0.1 0.06 0.02"/></geometry>
      <material name="yellow"><color rgba="0.9 0.9 0.2 1"/></material></visual>
    <collision><geometry><box size="0.1 0.06 0.02"/></geometry></collision>
  </link>

  <!-- 右腿大腿 -->
  <link name="right_thigh">
    <inertial>
      <origin xyz="0 0 -0.075"/>
      <mass value="0.5"/>
      <inertia ixx="0.01" iyy="0.01" izz="0.01" ixy="0" ixz="0" iyz="0"/>
    </inertial>
    <visual><geometry><box size="0.05 0.05 0.15"/></geometry>
      <material name="red"><color rgba="0.8 0.2 0.2 1"/></material></visual>
    <collision><geometry><box size="0.05 0.05 0.15"/></geometry></collision>
  </link>

  <!-- 右腿小腿 -->
  <link name="right_shin">
    <inertial>
      <origin xyz="0 0 -0.075"/>
      <mass value="0.3"/>
      <inertia ixx="0.005" iyy="0.005" izz="0.005" ixy="0" ixz="0" iyz="0"/>
    </inertial>
    <visual><geometry><box size="0.04 0.04 0.15"/></geometry>
      <material name="green"><color rgba="0.2 0.8 0.2 1"/></material></visual>
    <collision><geometry><box size="0.04 0.04 0.15"/></geometry></collision>
  </link>

  <!-- 右脚 -->
  <link name="right_foot">
    <inertial>
      <origin xyz="0 0 0"/>
      <mass value="0.2"/>
      <inertia ixx="0.002" iyy="0.002" izz="0.002" ixy="0" ixz="0" iyz="0"/>
    </inertial>
    <visual><geometry><box size="0.1 0.06 0.02"/></geometry>
      <material name="yellow"><color rgba="0.9 0.9 0.2 1"/></material></visual>
    <collision><geometry><box size="0.1 0.06 0.02"/></geometry></collision>
  </link>

  <!-- 关节 -->
  <joint name="left_hip" type="revolute">
    <parent link="torso"/>
    <child link="left_thigh"/>
    <origin xyz="0 0.1 -0.1" rpy="0 0 0"/>
    <axis xyz="1 0 0"/>
    <limit effort="20" velocity="2.0" lower="-1.0" upper="1.0"/>
  </joint>

  <joint name="left_knee" type="revolute">
    <parent link="left_thigh"/>
    <child link="left_shin"/>
    <origin xyz="0 0 -0.15" rpy="0 0 0"/>
    <axis xyz="1 0 0"/>
    <limit effort="15" velocity="2.0" lower="0" upper="2.0"/>
  </joint>

  <joint name="left_ankle" type="fixed">
    <parent link="left_shin"/>
    <child link="left_foot"/>
    <origin xyz="0 0 -0.15" rpy="0 0 0"/>
  </joint>

  <joint name="right_hip" type="revolute">
    <parent link="torso"/>
    <child link="right_thigh"/>
    <origin xyz="0 -0.1 -0.1" rpy="0 0 0"/>
    <axis xyz="1 0 0"/>
    <limit effort="20" velocity="2.0" lower="-1.0" upper="1.0"/>
  </joint>

  <joint name="right_knee" type="revolute">
    <parent link="right_thigh"/>
    <child link="right_shin"/>
    <origin xyz="0 0 -0.15" rpy="0 0 0"/>
    <axis xyz="1 0 0"/>
    <limit effort="15" velocity="2.0" lower="0" upper="2.0"/>
  </joint>

  <joint name="right_ankle" type="fixed">
    <parent link="right_shin"/>
    <child link="right_foot"/>
    <origin xyz="0 0 -0.15" rpy="0 0 0"/>
  </joint>

</robot>
